Workbook

Sheet Operatsiyalar
A1: Operatsiyalar jurnali
A2: Bot yozadigan asosiy jadval. Mijoz va summa shu yerga tushadi.
A4: Sana | B4: Vaqt | C4: Mijoz_ID | D4: Mijoz_nomi | E4: Turi | F4: Valyuta | G4: Summa | H4: Kurs | I4: Summa_uzs | J4: Summa_usd | K4: Izoh | L4: Telegram_user | M4: Matn | N4: Manba
A5: 2026-04-08 | B5: 21:04:22 | C5: 1 | D5: Farruh aka | E5: kirim | F5: UZS | G5: 100 | H5: 12100 | I5: 100 | J5: 0.0082644628 | K5: Telegram orqali kirim | L5: @elya_classic | M5: kirim UZS 100 Farruh aka | N5: matn
A6: 2026-04-08 | B6: 21:20:44 | C6: 1 | D6: Farruh aka | E6: chiqim | F6: USD | G6: 15 | H6: 12200 | I6: 183000 | J6: 15 | K6: Telegram orqali chiqim | L6: @Zapchast_2121 | M6: chiqim USD 15 Farruh aka | N6: matn
A7: 2026-04-11 | B7: 13:19:24 | F7: UZS | K7: Murodjon | L7: @Zapchast_2121 | M7: Murodjon | N7: matn
A8: 2026-04-11 | B8: 13:19:46 | F8: UZS | K8: Murotjon | L8: @Zapchast_2121 | M8: Murotjon | N8: matn
A9: 2026-04-11 | B9: 13:20:06 | F9: UZS | K9: Murodjon | L9: @Zapchast_2121 | M9: Murodjon | N9: matn
A10: 2026-04-11 | B10: 13:20:28 | F10: UZS | K10: D:\TOTLI BI\external\telegram_sheets_bot\templates\mijoz_hisob_kitobi.xlsx Murodjon | L10: @Zapchast_2121 | M10: D:\TOTLI BI\external\telegram_sheets_bot\templates\mijoz_hisob_kitobi.xlsx Murodjon | N10: matn
A11: 2026-04-11 | B11: 13:24:09 | F11: UZS | K11: Mutex | L11: @Zapchast_2121 | M11: Mutex | N11: matn
A12: 2026-04-11 | B12: 13:24:26 | F12: UZS | K12: Islomxon Usta Ozi | L12: @Zapchast_2121 | M12: Islomxon Usta Ozi | N12: matn
A13: 2026-04-12 | B13: 16:33:11 | F13: UZS | K13: Murotjon | L13: @Zapchast_2121 | M13: Murotjon | N13: matn
A14: 2026-04-12 | B14: 16:33:44 | F14: UZS | K14: D:\TOTLI BI\external\telegram_sheets_bot\templates\mijoz_hisob_kitobi.xlsx | L14: @Zapchast_2121 | M14: D:\TOTLI BI\external\telegram_sheets_bot\templates\mijoz_hisob_kitobi.xlsx | N14: matn
A15: 2026-04-12 | B15: 16:46:29 | F15: UZS | K15: Abdumalik A Balshivik | L15: @Zapchast_2121 | M15: Abdumalik A Balshivik | N15: matn
A16: 2026-04-13 | B16: 11:35:24 | C16: 2 | D16: Yuksalish | E16: chiqim | F16: UZS | G16: 7642000 | H16: 12200 | I16: 7642000 | J16: 626.39344 | K16: Telegram orqali chiqim | L16: @Zapchast_2121 | M16: chiqim UZS 7 642 000 Yuksalish | N16: matn
A17: 2026-04-13 | B17: 11:40:54 | C17: 2 | D17: Yuksalish | E17: chiqim | F17: USD | G17: 842 | H17: 12200 | I17: 10272400 | J17: 842 | K17: Telegram orqali chiqim | L17: @Zapchast_2121 | M17: chiqim USD 842 Yuksalish | N17: matn
A18: 2026-04-13 | B18: 13:21:52 | C18: 4 | D18: Abdumalik Aka Eski | E18: chiqim | F18: UZS | G18: 11062000 | H18: 12160 | I18: 11062000 | J18: 909.70395 | K18: Telegram orqali chiqim | L18: @Zapchast_2121 | M18: chiqim UZS 11 062 000 Abdumalik Aka Eski | N18: matn
A19: 2026-04-13 | B19: 13:22:14 | C19: 4 | D19: Abdumalik Aka Eski | E19: chiqim | F19: USD | G19: 262.8 | H19: 12160 | I19: 3195648 | J19: 262.8 | K19: Telegram orqali chiqim | L19: @Zapchast_2121 | M19: chiqim USD 262.8 Abdumalik Aka Eski | N19: matn
A20: 2026-04-13 | B20: 13:24:21 | C20: 5 | D20: Dilshod Aka | E20: chiqim | F20: UZS | G20: 2650000 | H20: 12160 | I20: 2650000 | J20: 217.92763 | K20: Telegram orqali chiqim | L20: @Zapchast_2121 | M20: chiqim UZS 2 650 000 Dilshod Aka | N20: matn
A21: 2026-04-13 | B21: 13:24:55 | C21: 5 | D21: Dilshod Aka | E21: chiqim | F21: USD | G21: 1268 | H21: 12160 | I21: 15418880 | J21: 1268 | K21: Telegram orqali chiqim | L21: @Zapchast_2121 | M21: chiqim USD 1 268 Dilshod Aka | N21: matn
A22: 2026-04-13 | B22: 13:26:02 | C22: 7 | D22: Feruz Apa | E22: chiqim | F22: UZS | G22: 5266000 | H22: 12160 | I22: 5266000 | J22: 433.05921 | K22: Telegram orqali chiqim | L22: @Zapchast_2121 | M22: chiqim UZS 5 266 000 Feruz Apa | N22: matn
A23: 2026-04-13 | B23: 13:26:16 | C23: 7 | D23: Feruz Apa | E23: chiqim | F23: USD | G23: 36 | H23: 12160 | I23: 437760 | J23: 36 | K23: Telegram orqali chiqim | L23: @Zapchast_2121 | M23: chiqim USD 36 Feruz Apa | N23: matn
A24: 2026-04-13 | B24: 13:27:03 | C24: 8 | D24: Abdurahmon | E24: chiqim | F24: UZS | G24: 14661000 | H24: 12160 | I24: 14661000 | J24: 1205.6743 | K24: Telegram orqali chiqim | L24: @Zapchast_2121 | M24: chiqim UZS 14 661 000 Abdurahmon | N24: matn
A25: 2026-04-13 | B25: 13:29:32 | C25: 8 | D25: Abdurahmon | E25: chiqim | F25: USD | G25: 1600 | H25: 12160 | I25: 19456000 | J25: 1600 | K25: Telegram orqali chiqim | L25: @Zapchast_2121 | M25: chiqim USD 1 600 Abdurahmon | N25: matn
A26: 2026-04-13 | B26: 13:30:39 | C26: 10 | D26: Mutex | E26: chiqim | F26: UZS | G26: 10000000 | H26: 12160 | I26: 10000000 | J26: 822.36842 | K26: Telegram orqali chiqim | L26: @Zapchast_2121 | M26: chiqim UZS 10 000 000 Mutex | N26: matn
A27: 2026-04-13 | B27: 13:30:51 | C27: 10 | D27: Mutex | E27: chiqim | F27: USD | G27: 3195 | H27: 12160 | I27: 38851200 | J27: 3195 | K27: Telegram orqali chiqim | L27: @Zapchast_2121 | M27: chiqim USD 3 195 Mutex | N27: matn
... A76: 2026-04-18 | B76: 17:26:44 | C76: 22 | D76: Abdumalik A Bal | E76: chiqim | F76: USD | G76: 7 | H76: 12170 | I76: 85190 | J76: 7 | K76: Telegram orqali chiqim | L76: @Zapchast_2121 | M76: chiqim USD 7 Abdumalik A Bal | N76: matn
A77: 2026-04-18 | B77: 17:27:08 | F77: UZS | G77: 175000 | I77: 175000 | J77: 0 | K77: 175000 | L77: @Zapchast_2121 | M77: 175000 | N77: matn
A78: 2026-04-18 | B78: 17:27:34 | C78: 23 | D78: Abdumalik A 2323 | E78: chiqim | F78: UZS | G78: 175000 | H78: 12170 | I78: 175000 | J78: 14.379622 | K78: Telegram orqali chiqim | L78: @Zapchast_2121 | M78: chiqim UZS 175 000 Abdumalik A 2323 | N78: matn
A79: 2026-04-19 | B79: 13:30:14 | C79: 8 | D79: Abdurahmon | E79: kirim | F79: USD | G79: 1000 | H79: 12150 | I79: 12150000 | J79: 1000 | K79: Telegram orqali kirim | L79: @Zapchast_2121 | M79: kirim USD 1 000 Abdurahmon | N79: matn
A80: 2026-04-19 | B80: 17:51:04 | C80: 19 | D80: Ilxom Aka 0083 | E80: chiqim | F80: UZS | G80: 747000 | H80: 12150 | I80: 747000 | J80: 61.481481 | K80: Telegram orqali chiqim | L80: @Zapchast_2121 | M80: chiqim UZS 747 000 Ilxom Aka 0083 | N80: matn
A81: 2026-04-19 | B81: 17:51:36 | C81: 26 | D81: Avaz Aka Marg'ilon | E81: chiqim | F81: USD | G81: 15 | H81: 12150 | I81: 182250 | J81: 15 | K81: Telegram orqali chiqim | L81: @Zapchast_2121 | M81: chiqim USD 15 Avaz Aka Marg'ilon | N81: matn
A82: 2026-04-19 | B82: 17:52:01 | C82: 14 | D82: Alisher Aka Usta | E82: chiqim | F82: USD | G82: 40 | H82: 12150 | I82: 486000 | J82: 40 | K82: Telegram orqali chiqim | L82: @Zapchast_2121 | M82: chiqim USD 40 Alisher Aka Usta | N82: matn
A83: 2026-04-19 | B83: 17:52:54 | C83: 23 | D83: Abdumalik A 2323 | E83: chiqim | F83: USD | G83: 8 | H83: 12150 | I83: 97200 | J83: 8 | K83: Telegram orqali chiqim | L83: @Zapchast_2121 | M83: chiqim USD 8 Abdumalik A 2323 | N83: matn
A84: 2026-04-20 | B84: 17:40:10 | C84: 8 | D84: Abdurahmon | E84: chiqim | F84: UZS | G84: 750000 | H84: 12120 | I84: 750000 | J84: 61.881188 | K84: Telegram orqali chiqim | L84: @Zapchast_2121 | M84: chiqim UZS 750 000 Abdurahmon | N84: matn
A85: 2026-04-20 | B85: 17:42:07 | C85: 2 | D85: Yuksalish | E85: chiqim | F85: UZS | G85: 900000 | H85: 12120 | I85: 900000 | J85: 74.257426 | K85: Telegram orqali chiqim | L85: @Zapchast_2121 | M85: chiqim UZS 900 000 Yuksalish | N85: matn
A86: 2026-04-20 | B86: 17:42:42 | C86: 2 | D86: Yuksalish | E86: chiqim | F86: USD | G86: 70 | H86: 12120 | I86: 848400 | J86: 70 | K86: Telegram orqali chiqim | L86: @Zapchast_2121 | M86: chiqim USD 70 Yuksalish | N86: matn
A87: 2026-04-22 | B87: 18:06:25 | C87: 22 | D87: Abdumalik A Bal | E87: chiqim | F87: USD | G87: 6 | H87: 12080 | I87: 72480 | J87: 6 | K87: Telegram orqali chiqim | L87: @Zapchast_2121 | M87: chiqim USD 6 Abdumalik A Bal | N87: matn
A88: 2026-04-22 | B88: 18:07:32 | C88: 7 | D88: Feruz Apa | E88: chiqim | F88: UZS | G88: 804000 | H88: 12080 | I88: 804000 | J88: 66.556291 | K88: Telegram orqali chiqim | L88: @Zapchast_2121 | M88: chiqim UZS 804 000 Feruz Apa | N88: matn
A89: 2026-04-22 | B89: 18:07:49 | C89: 7 | D89: Feruz Apa | E89: chiqim | F89: USD | G89: 28.6 | H89: 12080 | I89: 345488 | J89: 28.6 | K89: Telegram orqali chiqim | L89: @Zapchast_2121 | M89: chiqim USD 28.6 Feruz Apa | N89: matn
...

Sheet Mijozlar
A1: Mijozlar bazasi
A2: Mijozlarni shu yerda saqlaysiz. Formulalar avtomatik hisoblaydi.
A4: ID | B4: Nomi | C4: Telefon | D4: Boshlang'ich_qarz_uzs | E4: Boshlang'ich_qarz_usd | F4: =IF(A4="","",SUMIFS(Operatsiyalar!$I:$I,Operatsiyalar!$C:$C,A4,Operatsiyalar!$E:$E,"kirim")) | G4: =IF(A4="","",SUMIFS(Operatsiyalar!$J:$J,Operatsiyalar!$C:$C,A4,Operatsiyalar!$E:$E,"kirim")) | H4: =IF(A4="","",SUMIFS(Operatsiyalar!$I:$I,Operatsiyalar!$C:$C,A4,Operatsiyalar!$E:$E,"chiqim")) | I4: =IF(A4="","",SUMIFS(Operatsiyalar!$J:$J,Operatsiyalar!$C:$C,A4,Operatsiyalar!$E:$E,"chiqim")) | J4: =IF(A4="","",D4+H4-F4) | K4: =IF(A4="","",E4+I4-G4)
A5: 1 | B5: Farruh aka | C5: 905673344 | D5: 0 | E5: 1 | F5: =SUMIFS(Operatsiyalar!$I:$I,Operatsiyalar!$C:$C,A5,Operatsiyalar!$E:$E,"kirim") | G5: =SUMIFS(Operatsiyalar!$J:$J,Operatsiyalar!$C:$C,A5,Operatsiyalar!$E:$E,"kirim") | H5: =SUMIFS(Operatsiyalar!$I:$I,Operatsiyalar!$C:$C,A5,Operatsiyalar!$E:$E,"chiqim") | I5: =SUMIFS(Operatsiyalar!$J:$J,Operatsiyalar!$C:$C,A5,Operatsiyalar!$E:$E,"chiqim") | J5: =D5+H5-F5 | K5: =E5+I5-G5
A6: 2 | B6: Yuksalish | C6: 907072020 | D6: 0 | E6: 0 | F6: =SUMIFS(Operatsiyalar!$I:$I,Operatsiyalar!$C:$C,A6,Operatsiyalar!$E:$E,"kirim") | G6: =SUMIFS(Operatsiyalar!$J:$J,Operatsiyalar!$C:$C,A6,Operatsiyalar!$E:$E,"kirim") | H6: =SUMIFS(Operatsiyalar!$I:$I,Operatsiyalar!$C:$C,A6,Operatsiyalar!$E:$E,"chiqim") | I6: =SUMIFS(Operatsiyalar!$J:$J,Operatsiyalar!$C:$C,A6,Operatsiyalar!$E:$E,"chiqim") | J6: =D6+H6-F6 | K6: =E6+I6-G6
A7: 3 | B7: Sardor Aka | C7: 911477279 | D7: 0 | E7: 0 | F7: =SUMIFS(Operatsiyalar!$I:$I,Operatsiyalar!$C:$C,A7,Operatsiyalar!$E:$E,"kirim") | G7: =SUMIFS(Operatsiyalar!$J:$J,Operatsiyalar!$C:$C,A7,Operatsiyalar!$E:$E,"kirim") | H7: =SUMIFS(Operatsiyalar!$I:$I,Operatsiyalar!$C:$C,A7,Operatsiyalar!$E:$E,"chiqim") | I7: =SUMIFS(Operatsiyalar!$J:$J,Operatsiyalar!$C:$C,A7,Operatsiyalar!$E:$E,"chiqim") | J7: =D7+H7-F7 | K7: =E7+I7-G7
A8: 4 | B8: Abdumalik Aka Eski | C8: 916962323 | D8: 0 | E8: 0 | F8: =SUMIFS(Operatsiyalar!$I:$I,Operatsiyalar!$C:$C,A8,Operatsiyalar!$E:$E,"kirim") | G8: =SUMIFS(Operatsiyalar!$J:$J,Operatsiyalar!$C:$C,A8,Operatsiyalar!$E:$E,"kirim") | H8: =SUMIFS(Operatsiyalar!$I:$I,Operatsiyalar!$C:$C,A8,Operatsiyalar!$E:$E,"chiqim") | I8: =SUMIFS(Operatsiyalar!$J:$J,Operatsiyalar!$C:$C,A8,Operatsiyalar!$E:$E,"chiqim") | J8: =D8+H8-F8 | K8: =E8+I8-G8
A9: 5 | B9: Dilshod Aka | C9: 911393006 | D9: 0 | E9: 0 | F9: =SUMIFS(Operatsiyalar!$I:$I,Operatsiyalar!$C:$C,A9,Operatsiyalar!$E:$E,"kirim") | G9: =SUMIFS(Operatsiyalar!$J:$J,Operatsiyalar!$C:$C,A9,Operatsiyalar!$E:$E,"kirim") | H9: =SUMIFS(Operatsiyalar!$I:$I,Operatsiyalar!$C:$C,A9,Operatsiyalar!$E:$E,"chiqim") | I9: =SUMIFS(Operatsiyalar!$J:$J,Operatsiyalar!$C:$C,A9,Operatsiyalar!$E:$E,"chiqim") | J9: =D9+H9-F9 | K9: =E9+I9-G9
A10: 6 | B10: Obbos Aka | C10: 903663311 | D10: 0 | E10: 0 | F10: =SUMIFS(Operatsiyalar!$I:$I,Operatsiyalar!$C:$C,A10,Operatsiyalar!$E:$E,"kirim") | G10: =SUMIFS(Operatsiyalar!$J:$J,Operatsiyalar!$C:$C,A10,Operatsiyalar!$E:$E,"kirim") | H10: =SUMIFS(Operatsiyalar!$I:$I,Operatsiyalar!$C:$C,A10,Operatsiyalar!$E:$E,"chiqim") | I10: =SUMIFS(Operatsiyalar!$J:$J,Operatsiyalar!$C:$C,A10,Operatsiyalar!$E:$E,"chiqim") | J10: =D10+H10-F10 | K10: =E10+I10-G10
A11: 7 | B11: Feruz Apa | C11: 916902200 | D11: 0 | E11: 0 | F11: =SUMIFS(Operatsiyalar!$I:$I,Operatsiyalar!$C:$C,A11,Operatsiyalar!$E:$E,"kirim") | G11: =SUMIFS(Operatsiyalar!$J:$J,Operatsiyalar!$C:$C,A11,Operatsiyalar!$E:$E,"kirim") | H11: =SUMIFS(Operatsiyalar!$I:$I,Operatsiyalar!$C:$C,A11,Operatsiyalar!$E:$E,"chiqim") | I11: =SUMIFS(Operatsiyalar!$J:$J,Operatsiyalar!$C:$C,A11,Operatsiyalar!$E:$E,"chiqim") | J11: =D11+H11-F11 | K11: =E11+I11-G11
A12: 8 | B12: Abdurahmon | C12: 905900070 | D12: 0 | E12: 0 | F12: =SUMIFS(Operatsiyalar!$I:$I,Operatsiyalar!$C:$C,A12,Operatsiyalar!$E:$E,"kirim") | G12: =SUMIFS(Operatsiyalar!$J:$J,Operatsiyalar!$C:$C,A12,Operatsiyalar!$E:$E,"kirim") | H12: =SUMIFS(Operatsiyalar!$I:$I,Operatsiyalar!$C:$C,A12,Operatsiyalar!$E:$E,"chiqim") | I12: =SUMIFS(Operatsiyalar!$J:$J,Operatsiyalar!$C:$C,A12,Operatsiyalar!$E:$E,"chiqim") | J12: =D12+H12-F12 | K12: =E12+I12-G12
A13: 10 | B13: Mutex | C13: 907777772 | D13: 0 | E13: 0 | F13: =SUMIFS(Operatsiyalar!$I:$I,Operatsiyalar!$C:$C,A13,Operatsiyalar!$E:$E,"kirim") | G13: =SUMIFS(Operatsiyalar!$J:$J,Operatsiyalar!$C:$C,A13,Operatsiyalar!$E:$E,"kirim") | H13: =SUMIFS(Operatsiyalar!$I:$I,Operatsiyalar!$C:$C,A13,Operatsiyalar!$E:$E,"chiqim") | I13: =SUMIFS(Operatsiyalar!$J:$J,Operatsiyalar!$C:$C,A13,Operatsiyalar!$E:$E,"chiqim") | J13: =D13+H13-F13 | K13: =E13+I13-G13
A14: 11 | B14: Murotjon | C14: 912059898 | D14: 0 | E14: 0 | F14: =SUMIFS(Operatsiyalar!$I:$I,Operatsiyalar!$C:$C,A14,Operatsiyalar!$E:$E,"kirim") | G14: =SUMIFS(Operatsiyalar!$J:$J,Operatsiyalar!$C:$C,A14,Operatsiyalar!$E:$E,"kirim") | H14: =SUMIFS(Operatsiyalar!$I:$I,Operatsiyalar!$C:$C,A14,Operatsiyalar!$E:$E,"chiqim") | I14: =SUMIFS(Operatsiyalar!$J:$J,Operatsiyalar!$C:$C,A14,Operatsiyalar!$E:$E,"chiqim") | J14: =D14+H14-F14 | K14: =E14+I14-G14
A15: 12 | B15: Islomxon Usta eski | C15: 946656768 | D15: 0 | E15: 0 | F15: =SUMIFS(Operatsiyalar!$I:$I,Operatsiyalar!$C:$C,A15,Operatsiyalar!$E:$E,"kirim") | G15: =SUMIFS(Operatsiyalar!$J:$J,Operatsiyalar!$C:$C,A15,Operatsiyalar!$E:$E,"kirim") | H15: =SUMIFS(Operatsiyalar!$I:$I,Operatsiyalar!$C:$C,A15,Operatsiyalar!$E:$E,"chiqim") | I15: =SUMIFS(Operatsiyalar!$J:$J,Operatsiyalar!$C:$C,A15,Operatsiyalar!$E:$E,"chiqim") | J15: =D15+H15-F15 | K15: =E15+I15-G15
A16: 14 | B16: Alisher Aka Usta | C16: 905862874 | D16: 0 | E16: 0 | F16: =SUMIFS(Operatsiyalar!$I:$I,Operatsiyalar!$C:$C,A16,Operatsiyalar!$E:$E,"kirim") | G16: =SUMIFS(Operatsiyalar!$J:$J,Operatsiyalar!$C:$C,A16,Operatsiyalar!$E:$E,"kirim") | H16: =SUMIFS(Operatsiyalar!$I:$I,Operatsiyalar!$C:$C,A16,Operatsiyalar!$E:$E,"chiqim") | I16: =SUMIFS(Operatsiyalar!$J:$J,Operatsiyalar!$C:$C,A16,Operatsiyalar!$E:$E,"chiqim") | J16: =D16+H16-F16 | K16: =E16+I16-G16
... A29: 27 | B29: Islomxon usta Ganjiravon | C29: 946656768 | D29: 4752000 | E29: 0 | F29: =SUMIFS(Operatsiyalar!$I:$I,Operatsiyalar!$C:$C,A29,Operatsiyalar!$E:$E,"kirim") | G29: =SUMIFS(Operatsiyalar!$J:$J,Operatsiyalar!$C:$C,A29,Operatsiyalar!$E:$E,"kirim") | H29: =SUMIFS(Operatsiyalar!$I:$I,Operatsiyalar!$C:$C,A29,Operatsiyalar!$E:$E,"chiqim") | I29: =SUMIFS(Operatsiyalar!$J:$J,Operatsiyalar!$C:$C,A29,Operatsiyalar!$E:$E,"chiqim") | J29: =D29+H29-F29 | K29: =E29+I29-G29
F30: =IF(A34="","",SUMIFS(Operatsiyalar!$I:$I,Operatsiyalar!$C:$C,A34,Operatsiyalar!$E:$E,"kirim")) | G30: =IF(A34="","",SUMIFS(Operatsiyalar!$J:$J,Operatsiyalar!$C:$C,A34,Operatsiyalar!$E:$E,"kirim")) | H30: =IF(A34="","",SUMIFS(Operatsiyalar!$I:$I,Operatsiyalar!$C:$C,A34,Operatsiyalar!$E:$E,"chiqim")) | I30: =IF(A34="","",SUMIFS(Operatsiyalar!$J:$J,Operatsiyalar!$C:$C,A34,Operatsiyalar!$E:$E,"chiqim")) | J30: =IF(A34="","",D34+H34-F34) | K30: =IF(A34="","",E34+I34-G34)
F31: =IF(A35="","",SUMIFS(Operatsiyalar!$I:$I,Operatsiyalar!$C:$C,A35,Operatsiyalar!$E:$E,"kirim")) | G31: =IF(A35="","",SUMIFS(Operatsiyalar!$J:$J,Operatsiyalar!$C:$C,A35,Operatsiyalar!$E:$E,"kirim")) | H31: =IF(A35="","",SUMIFS(Operatsiyalar!$I:$I,Operatsiyalar!$C:$C,A35,Operatsiyalar!$E:$E,"chiqim")) | I31: =IF(A35="","",SUMIFS(Operatsiyalar!$J:$J,Operatsiyalar!$C:$C,A35,Operatsiyalar!$E:$E,"chiqim")) | J31: =IF(A35="","",D35+H35-F35) | K31: =IF(A35="","",E35+I35-G35)
F32: =IF(A36="","",SUMIFS(Operatsiyalar!$I:$I,Operatsiyalar!$C:$C,A36,Operatsiyalar!$E:$E,"kirim")) | G32: =IF(A36="","",SUMIFS(Operatsiyalar!$J:$J,Operatsiyalar!$C:$C,A36,Operatsiyalar!$E:$E,"kirim")) | H32: =IF(A36="","",SUMIFS(Operatsiyalar!$I:$I,Operatsiyalar!$C:$C,A36,Operatsiyalar!$E:$E,"chiqim")) | I32: =IF(A36="","",SUMIFS(Operatsiyalar!$J:$J,Operatsiyalar!$C:$C,A36,Operatsiyalar!$E:$E,"chiqim")) | J32: =IF(A36="","",D36+H36-F36) | K32: =IF(A36="","",E36+I36-G36)
F33: =IF(A37="","",SUMIFS(Operatsiyalar!$I:$I,Operatsiyalar!$C:$C,A37,Operatsiyalar!$E:$E,"kirim")) | G33: =IF(A37="","",SUMIFS(Operatsiyalar!$J:$J,Operatsiyalar!$C:$C,A37,Operatsiyalar!$E:$E,"kirim")) | H33: =IF(A37="","",SUMIFS(Operatsiyalar!$I:$I,Operatsiyalar!$C:$C,A37,Operatsiyalar!$E:$E,"chiqim")) | I33: =IF(A37="","",SUMIFS(Operatsiyalar!$J:$J,Operatsiyalar!$C:$C,A37,Operatsiyalar!$E:$E,"chiqim")) | J33: =IF(A37="","",D37+H37-F37) | K33: =IF(A37="","",E37+I37-G37)
F34: =IF(A38="","",SUMIFS(Operatsiyalar!$I:$I,Operatsiyalar!$C:$C,A38,Operatsiyalar!$E:$E,"kirim")) | G34: =IF(A38="","",SUMIFS(Operatsiyalar!$J:$J,Operatsiyalar!$C:$C,A38,Operatsiyalar!$E:$E,"kirim")) | H34: =IF(A38="","",SUMIFS(Operatsiyalar!$I:$I,Operatsiyalar!$C:$C,A38,Operatsiyalar!$E:$E,"chiqim")) | I34: =IF(A38="","",SUMIFS(Operatsiyalar!$J:$J,Operatsiyalar!$C:$C,A38,Operatsiyalar!$E:$E,"chiqim")) | J34: =IF(A38="","",D38+H38-F38) | K34: =IF(A38="","",E38+I38-G38)
F35: =IF(A39="","",SUMIFS(Operatsiyalar!$I:$I,Operatsiyalar!$C:$C,A39,Operatsiyalar!$E:$E,"kirim")) | G35: =IF(A39="","",SUMIFS(Operatsiyalar!$J:$J,Operatsiyalar!$C:$C,A39,Operatsiyalar!$E:$E,"kirim")) | H35: =IF(A39="","",SUMIFS(Operatsiyalar!$I:$I,Operatsiyalar!$C:$C,A39,Operatsiyalar!$E:$E,"chiqim")) | I35: =IF(A39="","",SUMIFS(Operatsiyalar!$J:$J,Operatsiyalar!$C:$C,A39,Operatsiyalar!$E:$E,"chiqim")) | J35: =IF(A39="","",D39+H39-F39) | K35: =IF(A39="","",E39+I39-G39)
F36: =IF(A40="","",SUMIFS(Operatsiyalar!$I:$I,Operatsiyalar!$C:$C,A40,Operatsiyalar!$E:$E,"kirim")) | G36: =IF(A40="","",SUMIFS(Operatsiyalar!$J:$J,Operatsiyalar!$C:$C,A40,Operatsiyalar!$E:$E,"kirim")) | H36: =IF(A40="","",SUMIFS(Operatsiyalar!$I:$I,Operatsiyalar!$C:$C,A40,Operatsiyalar!$E:$E,"chiqim")) | I36: =IF(A40="","",SUMIFS(Operatsiyalar!$J:$J,Operatsiyalar!$C:$C,A40,Operatsiyalar!$E:$E,"chiqim")) | J36: =IF(A40="","",D40+H40-F40) | K36: =IF(A40="","",E40+I40-G40)
F37: =IF(A41="","",SUMIFS(Operatsiyalar!$I:$I,Operatsiyalar!$C:$C,A41,Operatsiyalar!$E:$E,"kirim")) | G37: =IF(A41="","",SUMIFS(Operatsiyalar!$J:$J,Operatsiyalar!$C:$C,A41,Operatsiyalar!$E:$E,"kirim")) | H37: =IF(A41="","",SUMIFS(Operatsiyalar!$I:$I,Operatsiyalar!$C:$C,A41,Operatsiyalar!$E:$E,"chiqim")) | I37: =IF(A41="","",SUMIFS(Operatsiyalar!$J:$J,Operatsiyalar!$C:$C,A41,Operatsiyalar!$E:$E,"chiqim")) | J37: =IF(A41="","",D41+H41-F41) | K37: =IF(A41="","",E41+I41-G41)
F38: =IF(A42="","",SUMIFS(Operatsiyalar!$I:$I,Operatsiyalar!$C:$C,A42,Operatsiyalar!$E:$E,"kirim")) | G38: =IF(A42="","",SUMIFS(Operatsiyalar!$J:$J,Operatsiyalar!$C:$C,A42,Operatsiyalar!$E:$E,"kirim")) | H38: =IF(A42="","",SUMIFS(Operatsiyalar!$I:$I,Operatsiyalar!$C:$C,A42,Operatsiyalar!$E:$E,"chiqim")) | I38: =IF(A42="","",SUMIFS(Operatsiyalar!$J:$J,Operatsiyalar!$C:$C,A42,Operatsiyalar!$E:$E,"chiqim")) | J38: =IF(A42="","",D42+H42-F42) | K38: =IF(A42="","",E42+I42-G42)
F39: =IF(A43="","",SUMIFS(Operatsiyalar!$I:$I,Operatsiyalar!$C:$C,A43,Operatsiyalar!$E:$E,"kirim")) | G39: =IF(A43="","",SUMIFS(Operatsiyalar!$J:$J,Operatsiyalar!$C:$C,A43,Operatsiyalar!$E:$E,"kirim")) | H39: =IF(A43="","",SUMIFS(Operatsiyalar!$I:$I,Operatsiyalar!$C:$C,A43,Operatsiyalar!$E:$E,"chiqim")) | I39: =IF(A43="","",SUMIFS(Operatsiyalar!$J:$J,Operatsiyalar!$C:$C,A43,Operatsiyalar!$E:$E,"chiqim")) | J39: =IF(A43="","",D43+H43-F43) | K39: =IF(A43="","",E43+I43-G43)
F40: =IF(A44="","",SUMIFS(Operatsiyalar!$I:$I,Operatsiyalar!$C:$C,A44,Operatsiyalar!$E:$E,"kirim")) | G40: =IF(A44="","",SUMIFS(Operatsiyalar!$J:$J,Operatsiyalar!$C:$C,A44,Operatsiyalar!$E:$E,"kirim")) | H40: =IF(A44="","",SUMIFS(Operatsiyalar!$I:$I,Operatsiyalar!$C:$C,A44,Operatsiyalar!$E:$E,"chiqim")) | I40: =IF(A44="","",SUMIFS(Operatsiyalar!$J:$J,Operatsiyalar!$C:$C,A44,Operatsiyalar!$E:$E,"chiqim")) | J40: =IF(A44="","",D44+H44-F44) | K40: =IF(A44="","",E44+I44-G44)
F41: =IF(A45="","",SUMIFS(Operatsiyalar!$I:$I,Operatsiyalar!$C:$C,A45,Operatsiyalar!$E:$E,"kirim")) | G41: =IF(A45="","",SUMIFS(Operatsiyalar!$J:$J,Operatsiyalar!$C:$C,A45,Operatsiyalar!$E:$E,"kirim")) | H41: =IF(A45="","",SUMIFS(Operatsiyalar!$I:$I,Operatsiyalar!$C:$C,A45,Operatsiyalar!$E:$E,"chiqim")) | I41: =IF(A45="","",SUMIFS(Operatsiyalar!$J:$J,Operatsiyalar!$C:$C,A45,Operatsiyalar!$E:$E,"chiqim")) | J41: =IF(A45="","",D45+H45-F45) | K41: =IF(A45="","",E45+I45-G45)
... F299: =IF(A303="","",SUMIFS(Operatsiyalar!$I:$I,Operatsiyalar!$C:$C,A303,Operatsiyalar!$E:$E,"kirim")) | G299: =IF(A303="","",SUMIFS(Operatsiyalar!$J:$J,Operatsiyalar!$C:$C,A303,Operatsiyalar!$E:$E,"kirim")) | H299: =IF(A303="","",SUMIFS(Operatsiyalar!$I:$I,Operatsiyalar!$C:$C,A303,Operatsiyalar!$E:$E,"chiqim")) | I299: =IF(A303="","",SUMIFS(Operatsiyalar!$J:$J,Operatsiyalar!$C:$C,A303,Operatsiyalar!$E:$E,"chiqim")) | J299: =IF(A303="","",D303+H303-F303) | K299: =IF(A303="","",E303+I303-G303)

Sheet Hisobot
A1: Ko'rsatkich | B1: UZS | C1: USD
A2: Mijozlar to'lagan | B2: =SUMIFS(Operatsiyalar!$I:$I,Operatsiyalar!$E:$E,"kirim") | C2: =SUMIFS(Operatsiyalar!$J:$J,Operatsiyalar!$E:$E,"kirim")
A3: Biz bergan | B3: =SUMIFS(Operatsiyalar!$I:$I,Operatsiyalar!$E:$E,"chiqim") | C3: =SUMIFS(Operatsiyalar!$J:$J,Operatsiyalar!$E:$E,"chiqim")
A4: Jami qarz qoldiq | B4: =B3-B2 | C4: =C3-C2
A5: Operatsiyalar soni | B5: =COUNTA(Operatsiyalar!$A:$A)-3
A6: Jami qarz qoldiq | B6: =B5-B4 | C6: =C5-C4
A7: Operatsiyalar soni | B7: =COUNTA(Operatsiyalar!$A:$A)-3
A9: Izoh | B9: Bot: Mijozlar -> amal -> valyuta -> summa -> kurs; Hisobot ikki valyutada chiqadi
